Workbook

Sheet SET-25
A1: ³PF/UF/CRM | B1: NOME DO MEDICO E | C1: FETU 25 | D1: APROV | E1: REJEI | F1: VL.REJ.VENDA | G1: VL.REJ.CUSTO | H1: INDICE³ | I1: 2026 | J1: DIFER | K1: %
A2: CRM-BA-808080 | B2: SOLICITACAO SEM PRESCRIT | C2: 413 | D2: 179 | E2: 234 | F2: 41312.3 | G2: 6525.27 | H2: 0.5666 | I2: =VLOOKUP(B2,'SET-26'!B$2:H$174,2,FALSE) -> 179 | J2: =I2-C2 -> -234 | K2: =J2/C2 -> -0.56658596 | L2: disconsdera | O2: ITEM | P2: 45901 | Q2: 46266 | R2: DIF
A3: CRM-BA-32587 | B3: BRENO SOUZA SILVA | C3: 219 | D3: 121 | E3: 98 | F3: 43816.95 | G3: 8349.52 | H3: 0.4475 | I3: =VLOOKUP(B3,'SET-26'!B$2:H$174,2,FALSE) -> 147 | J3: =I3-C3 -> -72 | K3: =J3/C3 -> -0.32876712 | O3: MAIS QUE 10 | P3: 37 | Q3: 23 | R3: =P3-Q3 -> 14 | S3: =R3/P3 -> 0.37837838
A4: CRM-BA-17611 | B4: NILZA SANTIAGO GRANATO | C4: 218 | D4: 142 | E4: 76 | F4: 13185.4 | G4: 2155.45 | H4: 0.3486 | I4: =VLOOKUP(B4,'SET-26'!B$2:H$174,2,FALSE) -> 116 | J4: =I4-C4 -> -102 | K4: =J4/C4 -> -0.46788991 | O4: TOTAL ORC | P4: =2407-66 -> 2341 | Q4: 1786 | R4: =P4-Q4 -> 555 | S4: =R4/P4 -> 0.23707817
A5: CRM-BA-22820 | B5: LORENA DE LIMA ABUDE SIL | C5: 171 | D5: 124 | E5: 47 | F5: 9037 | G5: 1397.63 | H5: 0.2749 | I5: =VLOOKUP(B5,'SET-26'!B$2:H$174,2,FALSE) -> 141 | J5: =I5-C5 -> -30 | K5: =J5/C5 -> -0.1754386 | O5: CONV | P5: 0.57 | Q5: 0.5 | R5: =P5-Q5 -> 0.07
A6: CRN-BA-10686 | B6: JOSE LUIZ CARDOSO ROCHA | C6: 105 | D6: 72 | E6: 33 | F6: 5054 | G6: 838.16 | H6: 0.3143 | I6: =VLOOKUP(B6,'SET-26'!B$2:H$174,2,FALSE) -> 76 | J6: =I6-C6 -> -29 | K6: =J6/C6 -> -0.27619048 | O6: TOTA MED | P6: 173 | Q6: 173 | R6: OK
A7: CRN-BA-8266 | B7: JONATAS RODRIGUES DE SAN | C7: 102 | D7: 79 | E7: 23 | F7: 6863.5 | G7: 1164.48 | H7: 0.2255 | I7: =VLOOKUP(B7,'SET-26'!B$2:H$174,2,FALSE) -> 58 | J7: =I7-C7 -> -44 | K7: =J7/C7 -> -0.43137255 | O7: MED 100% REJ | P7: 96 | Q7: 108 | R7: =Q7-P7 -> 12 | S7: =R7/P7 -> 0.125
A8: CRM-BA-13956 | B8: RENATA SANTANA ALBANO OL | C8: 71 | D8: 45 | E8: 26 | F8: 4350.5 | G8: 737.87 | H8: 0.3662 | I8: =VLOOKUP(B8,'SET-26'!B$2:H$174,2,FALSE) -> 50 | J8: =I8-C8 -> -21 | K8: =J8/C8 -> -0.29577465
A9: CRM-BA-11546 | B9: SIMONE DANTAS REBOUCAS | C9: 71 | D9: 51 | E9: 20 | F9: 2143.4 | G9: 250.76 | H9: 0.2817 | I9: =VLOOKUP(B9,'SET-26'!B$2:H$174,2,FALSE) -> 12 | J9: =I9-C9 -> -59 | K9: =J9/C9 -> -0.83098592
A10: CRM-BA-28850 | B10: ALLYSON AMARAL | C10: 55 | D10: 33 | E10: 22 | F10: 8663.5 | G10: 1831.15 | H10: 0.4 | I10: =VLOOKUP(B10,'SET-26'!B$2:H$174,2,FALSE) -> 67 | J10: =I10-C10 -> 12 | K10: =J10/C10 -> 0.21818182
A11: CRM-BA-28008 | B11: RAISA MENDEZ DE ARAUJO | C11: 53 | D11: 44 | E11: 9 | F11: 1285 | G11: 231.77 | H11: 0.1698 | I11: =VLOOKUP(B11,'SET-26'!B$2:H$174,2,FALSE) -> 47 | J11: =I11-C11 -> -6 | K11: =J11/C11 -> -0.11320755
A12: CRN-BA-7913 | B12: DIEGO DE JESUS MAURICIO | C12: 41 | D12: 26 | E12: 15 | F12: 6904 | G12: 1701.16 | H12: 0.3659 | I12: =VLOOKUP(B12,'SET-26'!B$2:H$174,2,FALSE) -> 6 | J12: =I12-C12 -> -35 | K12: =J12/C12 -> -0.85365854 | L12: xxxx
A13: CRM-BA-27714 | B13: PAULO OLIVEIRA SANTANA F | C13: 37 | D13: 30 | E13: 7 | F13: 1386.3 | G13: 228.68 | H13: 0.1892 | I13: =VLOOKUP(B13,'SET-26'!B$2:H$174,2,FALSE) -> 23 | J13: =I13-C13 -> -14 | K13: =J13/C13 -> -0.37837838 | L13: xxxx
A14: CRM-BA-24876 | B14: NEY FILHO | C14: 33 | D14: 25 | E14: 8 | F14: 1435.5 | G14: 284.26 | H14: 0.2424 | I14: =VLOOKUP(B14,'SET-26'!B$2:H$174,2,FALSE) -> 9 | J14: =I14-C14 -> -24 | K14: =J14/C14 -> -0.72727273
A15: CRM-BA-19575 | B15: VALTER SILVA CARDOSO FIL | C15: 33 | D15: 11 | E15: 22 | F15: 3368.5 | G15: 440.75 | H15: 0.6667 | I15: =VLOOKUP(B15,'SET-26'!B$2:H$174,2,FALSE) -> 11 | J15: =I15-C15 -> -22 | K15: =J15/C15 -> -0.66666667
A16: CRM-BA-27489 | B16: VICTOR EDUARDO ANDRADE M | C16: 28 | D16: 18 | E16: 10 | F16: 1910.5 | G16: 333.51 | H16: 0.3571 | I16: =VLOOKUP(B16,'SET-26'!B$2:H$174,2,FALSE) -> 19 | J16: =I16-C16 -> -9 | K16: =J16/C16 -> -0.32142857
A17: CRM-BA-14066 | B17: ERICO DA SILVA CARVALHO | C17: 20 | D17: 6 | E17: 14 | F17: 6711.5 | G17: 1275.06 | H17: 0.7 | I17: =VLOOKUP(B17,'SET-26'!B$2:H$174,2,FALSE) -> 6 | J17: =I17-C17 -> -14 | K17: =J17/C17 -> -0.7 | O17: CRN-BA-8262 | P17: NATALIA LIMA AMARAL | Q17: 66 | R17: 57 | S17: 9 | T17: 1323 | U17: 184.4 | V17: 0.1364 | W17: 0 | X17: =W17-Q17 -> -66
A18: CRN-BA-8914 | B18: LUCY GLADS BERNARDES GOU | C18: 18 | D18: 9 | E18: 9 | F18: 2160 | G18: 368.23 | H18: 0.5 | I18: 0 | J18: =I18-C18 -> -18 | K18: =J18/C18 -> -1
A19: CRM-BA-11166 | B19: ADRIANA MATOS BENJAMIN L | C19: 17 | D19: 0 | E19: 17 | F19: 1996 | G19: 248.97 | H19: 1 | I19: 0 | J19: =I19-C19 -> -17 | K19: =J19/C19 -> -1
A20: CRM-SP-225107 | B20: HELLEN GULNOSA | C20: 17 | D20: 10 | E20: 7 | F20: 1807 | G20: 280.15 | H20: 0.4118 | I20: 0 | J20: =I20-C20 -> -17 | K20: =J20/C20 -> -1 | O20: EFETUADOS
A21: CRN-BA-3633 | B21: TATILA DOS SANTOS LIMA | C21: 16 | D21: 7 | E21: 9 | F21: 2516 | G21: 584.22 | H21: 0.5625 | I21: =VLOOKUP(B21,'SET-26'!B$2:H$174,2,FALSE) -> 18 | J21: =I21-C21 -> 2 | K21: =J21/C21 -> 0.125 | O21: =SUM(C2:C176) -> 2341 | P21: =SUM(D2:D176) -> 1228
A22: CRM-BA-7840 | B22: JOSE AMERICO RESENDE JUN | C22: 15 | D22: 9 | E22: 6 | F22: 1327 | G22: 231.79 | H22: 0.4 | I22: 0 | J22: =I22-C22 -> -15 | K22: =J22/C22 -> -1 | P22: =P21/O21 -> 0.52456215
A23: CRN-BA-5453 | B23: ALEXSANDRA ROSA DOS SANT | C23: 14 | D23: 5 | E23: 9 | F23: 1234 | G23: 197.52 | H23: 0.6429 | I23: 0 | J23: =I23-C23 -> -14 | K23: =J23/C23 -> -1
A24: CRM-BA-31481 | B24: JHONATAS MASCARENHAS | C24: 14 | D24: 0 | E24: 14 | F24: 2786 | G24: 539.26 | H24: 1 | I24: 0 | J24: =I24-C24 -> -14 | K24: =J24/C24 -> -1
A25: CRM-BA-45358 | B25: JULIANNE LINO DE MENEZES | C25: 14 | D25: 7 | E25: 7 | F25: 951.5 | G25: 125.35 | H25: 0.5 | I25: =VLOOKUP(B25,'SET-26'!B$2:H$174,2,FALSE) -> 6 | J25: =I25-C25 -> -8 | K25: =J25/C25 -> -0.57142857
A26: CRM-SP-267036 | B26: RAFAEL CUNHA VIVAS | C26: 14 | D26: 8 | E26: 6 | F26: 1868.5 | G26: 300.78 | H26: 0.4286 | I26: =VLOOKUP(B26,'SET-26'!B$2:H$174,2,FALSE) -> 3 | J26: =I26-C26 -> -11 | K26: =J26/C26 -> -0.78571429
A27: CRBM-BA-21255 | B27: BRENDALINE FERREIRA TAVA | C27: 13 | D27: 11 | E27: 2 | F27: 262.5 | G27: 28.26 | H27: 0.1538 | I27: 0 | J27: =I27-C27 -> -13 | K27: =J27/C27 -> -1
A28: CRM-BA-32108 | B28: FELIPE BUTE BONFIM | C28: 13 | D28: 6 | E28: 7 | F28: 861.5 | G28: 122.39 | H28: 0.5385 | I28: =VLOOKUP(B28,'SET-26'!B$2:H$174,2,FALSE) -> 7 | J28: =I28-C28 -> -6 | K28: =J28/C28 -> -0.46153846
A29: CRM-BA-14604 | B29: RODRIGO OLIVEIRA GOMES D | C29: 13 | D29: 5 | E29: 8 | F29: 762.5 | G29: 92.36 | H29: 0.6154 | I29: 0 | J29: =I29-C29 -> -13 | K29: =J29/C29 -> -1
A30: CRM-RS-59528 | B30: VALDEMIR GONZAGA | C30: 13 | D30: 0 | E30: 13 | F30: 1887 | G30: 241.37 | H30: 1 | I30: 0 | J30: =I30-C30 -> -13 | K30: =J30/C30 -> -1
A31: CRM-DF-15741 | B31: BRUNO CESAR PAZ | C31: 11 | D31: 4 | E31: 7 | F31: 596.5 | G31: 54.45 | H31: 0.6364 | I31: 0 | J31: =I31-C31 -> -11 | K31: =J31/C31 -> -1
A32: CRM-BA-17681 | B32: FABIO NUNES LIMA | C32: 11 | D32: 10 | E32: 1 | F32: 80.5 | G32: 4.19 | H32: 0.0909 | I32: 0 | J32: =I32-C32 -> -11 | K32: =J32/C32 -> -1
A33: CRM-BA-46033 | B33: JAQUELINE LEU SANTOS | C33: 11 | D33: 6 | E33: 5 | F33: 773 | G33: 120.43 | H33: 0.4545 | I33: =VLOOKUP(B33,'SET-26'!B$2:H$174,2,FALSE) -> 2 | J33: =I33-C33 -> -9 | K33: =J33/C33 -> -0.81818182
A34: RMS-BA-12847 | B34: MERCIA ROSANA O. LIMA | C34: 11 | D34: 4 | E34: 7 | F34: 616.5 | G34: 71.35 | H34: 0.6364 | I34: 0 | J34: =I34-C34 -> -11 | K34: =J34/C34 -> -1
A35: CRM-BA-27500 | B35: CAMILA PORTO OLIVEIRA | C35: 10 | D35: 1 | E35: 9 | F35: 759 | G35: 105.56 | H35: 0.9 | I35: =VLOOKUP(B35,'SET-26'!B$2:H$174,2,FALSE) -> 28 | J35: =I35-C35 -> 18 | K35: =J35/C35 -> 1.8
A36: CRM-SP-240451 | B36: JULIA SILVESTRINI | C36: 10 | D36: 0 | E36: 10 | F36: 1498.5 | G36: 185.51 | H36: 1 | I36: 0 | J36: =I36-C36 -> -10 | K36: =J36/C36 -> -1
A37: CRM-BA-22798 | B37: JULIANA PACHECO PITANGA | C37: 10 | D37: 8 | E37: 2 | F37: 362 | G37: 51.88 | H37: 0.2 | I37: =VLOOKUP(B37,'SET-26'!B$2:H$174,2,FALSE) -> 8 | J37: =I37-C37 -> -2 | K37: =J37/C37 -> -0.2
A38: CRM-BA-27843 | B38: THAIS PAULA REIS | C38: 10 | D38: 9 | E38: 1 | F38: 61.5 | G38: 7.42 | H38: 0.1 | I38: =VLOOKUP(B38,'SET-26'!B$2:H$174,2,FALSE) -> 3 | J38: =I38-C38 -> -7 | K38: =J38/C38 -> -0.7
A39: CRM-RS-51863 | B39: BRENDON ICARO SILVA DONA | C39: 8 | D39: 0 | E39: 8 | F39: 1979.5 | G39: 306.47 | H39: 1 | I39: 0 | J39: =I39-C39 -> -8 | K39: =J39/C39 -> -1
A40: CRN-BA-16374 | B40: ISABELLE DOS SANTOS COST | C40: 8 | D40: 3 | E40: 5 | F40: 780 | G40: 113.7 | H40: 0.625 | I40: 0 | J40: =I40-C40 -> -8 | K40: =J40/C40 -> -1
...

Sheet SET-26
A1: ³PF/UF/CRM | B1: NOME DO MEDICO E | C1: FETU | D1: APROV | E1: REJEI | F1: VL.REJ.VENDA | G1: VL.REJ.CUSTO | H1: INDICE³
A2: CRF-BA-21266 | B2: ARTHUR SILVA BOMFIM | C2: 241 | D2: 115 | E2: 126 | F2: 25681.9 | G2: 5845.37 | H2: 0.5228
A3: CRM-BA-808080 | B3: SOLICITACAO SEM PRESCRIT | C3: 179 | D3: 56 | E3: 123 | F3: 20363.66 | G3: 3682.53 | H3: 0.6872 | M3: 108 MEDICOS 100% REJ
A4: CRM-BA-32587 | B4: BRENO SOUZA SILVA | C4: 147 | D4: 100 | E4: 47 | F4: 12960.26 | G4: 3322.13 | H4: 0.3197
A5: CRM-BA-22820 | B5: LORENA DE LIMA ABUDE SIL | C5: 141 | D5: 86 | E5: 55 | F5: 12718.05 | G5: 2811.99 | H5: 0.3901
A6: CRM-BA-17611 | B6: NILZA SANTIAGO GRANATO | C6: 116 | D6: 47 | E6: 69 | F6: 12028.4 | G6: 2437.21 | H6: 0.5948
A7: CRN-BA-10686 | B7: JOSE LUIZ CARDOSO ROCHA | C7: 76 | D7: 33 | E7: 43 | F7: 6698.8 | G7: 1495.54 | H7: 0.5658
A8: CRM-BA-28850 | B8: ALLYSON AMARAL | C8: 67 | D8: 39 | E8: 28 | F8: 10841.82 | G8: 2791.14 | H8: 0.4179
A9: CRN-BA-8266 | B9: JONATAS RODRIGUES DE SAN | C9: 58 | D9: 41 | E9: 17 | F9: 4609.2 | G9: 1183.16 | H9: 0.2931
A10: CRM-BA-13956 | B10: RENATA SANTANA ALBANO OL | C10: 50 | D10: 38 | E10: 12 | F10: 1889.44 | G10: 311.7 | H10: 0.24
A11: CRM-BA-28008 | B11: RAISA MENDEZ DE ARAUJO | C11: 47 | D11: 29 | E11: 18 | F11: 3722.55 | G11: 901.29 | H11: 0.383
A12: CRM-BA-27500 | B12: CAMILA PORTO OLIVEIRA | C12: 28 | D12: 21 | E12: 7 | F12: 1330.67 | G12: 232.06 | H12: 0.25
A13: CRM-BA-3448 | B13: ROLEMBERG MONTEIRO DA SI | C13: 24 | D13: 1 | E13: 23 | F13: 3735.2 | G13: 652.65 | H13: 0.9583
A14: CRM-BA-27714 | B14: PAULO OLIVEIRA SANTANA F | C14: 23 | D14: 22 | E14: 1 | F14: 183.75 | G14: 43.2 | H14: 0.0435
A15: CRM-BA-27489 | B15: VICTOR EDUARDO ANDRADE M | C15: 19 | D15: 14 | E15: 5 | F15: 822.79 | G15: 148.2 | H15: 0.2632
... A20: CRM-BA-11546 | B20: SIMONE DANTAS REBOUCAS | C20: 12 | D20: 4 | E20: 8 | F20: 1174.67 | G20: 181.94 | H20: 0.6667
A21: CRM-BA-43397 | B21: VICTORIA E€A DE BRITO | C21: 12 | D21: 11 | E21: 1 | F21: 429.5 | G21: 119.65 | H21: 0.0833 | M21: CRN-BA-8262 | N21: NATALIA LIMA AMARAL | O21: 634 | P21: 590 | Q21: 44 | R21: 9726.39 | S21: 1418.22 | T21: 0.0694
A22: CRM-BA-19575 | B22: VALTER SILVA CARDOSO FIL | C22: 11 | D22: 2 | E22: 9 | F22: 3064 | G22: 729.64 | H22: 0.8182
A23: CRBM-BA-16403 | B23: EURY R. R. JUNIOR | C23: 10 | D23: 0 | E23: 10 | F23: 2500.13 | G23: 506.86 | H23: 1
A24: CRM-BA-8222 | B24: DENISE MENESES FERREIRA | C24: 10 | D24: 0 | E24: 10 | F24: 2214.06 | G24: 351.99 | H24: 1
A25: CRM-RJ-12325442 | B25: BRUNO CARVALHO TEMOTEO | C25: 9 | D25: 0 | E25: 9 | F25: 2135 | G25: 321.83 | H25: 1
A26: CRN-BA-8861 | B26: QUERCIANE GONCALVES FREI | C26: 9 | D26: 0 | E26: 9 | F26: 1838.77 | G26: 388.98 | H26: 1
A27: CRF-BA-4839 | B27: BRUNO ANDRADE AMARAL | C27: 9 | D27: 1 | E27: 8 | F27: 1639.65 | G27: 356.95 | H27: 0.8889 | N27: efet | O27: aprov
A28: CRM-BA-24876 | B28: NEY FILHO | C28: 9 | D28: 2 | E28: 7 | F28: 1183.84 | G28: 232.39 | H28: 0.7778 | N28: =SUM(C2:C174) -> 1786 | O28: =SUM(D2:D174) -> 779
A29: CRM-BA-19717 | B29: GIOVANI DE SA ALMEIDA | C29: 9 | D29: 5 | E29: 4 | F29: 859.34 | G29: 173.21 | H29: 0.4444 | O29: =O28/N28 -> 0.43617021
A30: CRM-BA-13722 | B30: CHRISTINE PINTO ROSA | C30: 9 | D30: 6 | E30: 3 | F30: 433.5 | G30: 68.83 | H30: 0.3333
A31: CRN-BA-4260 | B31: JENIFFER PRATES FONSECA | C31: 8 | D31: 0 | E31: 8 | F31: 1354.35 | G31: 265.47 | H31: 1
A32: CRN-BA-8299 | B32: SANDRA COSTA DA SILVA ME | C32: 8 | D32: 4 | E32: 4 | F32: 356.5 | G32: 26.21 | H32: 0.5 | N32: 2420 | O32: 1369
A33: CRM-BA-22798 | B33: JULIANA PACHECO PITANGA | C33: 8 | D33: 5 | E33: 3 | F33: 549.87 | G33: 94.91 | H33: 0.375 | N33: =N28+O21 -> 2420 | O33: =O28+P21 -> 1369
A34: CRM-BA-27370 | B34: CAROLINA MARINHO | C34: 7 | D34: 0 | E34: 7 | F34: 1027.57 | G34: 213.41 | H34: 1
A35: CRM-BA-48299 | B35: LAYSA FORTUNA DE OLIVEIR | C35: 7 | D35: 0 | E35: 7 | F35: 961.25 | G35: 150.41 | H35: 1
A36: CRM-SP-193189 | B36: HELEN SUZANY PEREIRA MAG | C36: 7 | D36: 0 | E36: 7 | F36: 1192.1 | G36: 202.53 | H36: 1 | N36: 2663 | O36: 1612
A37: CRN-BA-22541 | B37: KILIANA CAMPOS TRINTADE | C37: 7 | D37: 0 | E37: 7 | F37: 1802.5 | G37: 363.03 | H37: 1 | N37: =N36-O21 -> 2029 | O37: =O36-P21 -> 1022
A38: CRM-BA-30418 | B38: CAROL AMPARO | C38: 7 | D38: 1 | E38: 6 | F38: 1608.21 | G38: 406.35 | H38: 0.8571 | O38: =O37/N37 -> 0.5036964
A39: CRM-BA-32108 | B39: FELIPE BUTE BONFIM | C39: 7 | D39: 1 | E39: 6 | F39: 774.17 | G39: 121.97 | H39: 0.8571
A40: CRM-BA-35823 | B40: ISABELLA DORIA NOVAIS | C40: 6 | D40: 0 | E40: 6 | F40: 771.95 | G40: 91.49 | H40: 1
A41: CRN-BA-11770 | B41: MARIANA DOS REIS | C41: 6 | D41: 0 | E41: 6 | F41: 712.5 | G41: 100.85 | H41: 1
A42: CRN-BA-25494 | B42: LEONARDO OLIVEIRA | C42: 6 | D42: 0 | E42: 6 | F42: 841.8 | G42: 99.37 | H42: 1
A43: CRM-BA-45358 | B43: JULIANNE LINO DE MENEZES | C43: 6 | D43: 1 | E43: 5 | F43: 973.89 | G43: 193.03 | H43: 0.8333
A44: CRM-BA-45376 | B44: LARA STEFHANY | C44: 6 | D44: 1 | E44: 5 | F44: 1185.89 | G44: 230.55 | H44: 0.8333
...
